<?xml version="1.0" encoding="utf-8"?>

<robot name="guard"
    xmlns:xacro="http://ros.org/wiki/xacro">

    <!-- Import guard ros2_control description -->
    <xacro:include filename="$(find rm_pioneer_description)/ros2_control/guard.ros2_control.xacro" />

    <link name="base_link" />

    <link name="yaw_link">
        <inertial>
            <origin xyz="6.5483E-08 -0.050209 -0.056865" rpy="0 0 0" />
            <mass value="0.54474" />
            <inertia ixx="0.00022219" ixy="-5.1209E-08" ixz="3.7372E-08" iyy="0.00026122" iyz="1.1456E-05" izz="0.0002457" />
        </inertial>
        <visual>
            <origin xyz="0 0 0" rpy="0 0 0" />
            <geometry>
                <mesh filename="package://rm_pioneer_description/meshes/guard/yaw_link.stl" />
            </geometry>
            <material name="">
                <color rgba="0.89804 0.91765 0.92941 1" />
            </material>
        </visual>
        <collision>
            <origin xyz="0 0 0" rpy="0 0 0" />
            <geometry>
                <mesh filename="package://rm_pioneer_description/meshes/guard/yaw_link.stl" />
            </geometry>
        </collision>
    </link>

    <joint name="yaw_joint" type="continuous">
        <origin xyz="0 0 0" rpy="0 0 0" />
        <parent link="base_link" />
        <child link="yaw_link" />
        <axis xyz="0 0 1" />
        <limit velocity="0" effort="30000"/>
    </joint>

    <link name="pitch_link">
        <inertial>
            <origin xyz="0.023038 -0.00034952 -0.022985" rpy="0 0 0" />
            <mass value="1.209" />
            <inertia ixx="0.00096057" ixy="-7.7082E-06" ixz="-1.5997E-06" iyy="0.0013203" iyz="4.1017E-07" izz="0.0020944" />
        </inertial>
        <visual>
            <origin xyz="0 0 0" rpy="0 0 0" />
            <geometry>
                <mesh filename="package://rm_pioneer_description/meshes/guard/pitch_link.stl" />
            </geometry>
            <material name="">
                <color rgba="0.89804 0.91765 0.92941 1" />
            </material>
        </visual>
        <collision>
            <origin xyz="0 0 0" rpy="0 0 0" />
            <geometry>
                <mesh filename="package://rm_pioneer_description/meshes/guard/pitch_link.stl" />
            </geometry>
        </collision>
    </link>

    <joint name="pitch_joint" type="revolute">
        <origin xyz="0 0.003 -0.074" rpy="0 0 0" />
        <parent link="yaw_link" />
        <child link="pitch_link" />
        <axis xyz="0 1 0" />
        <limit lower="0.0" upper="0.5" velocity="0" effort="30000"/>
    </joint>

    <link name="shooter_link" />

    <joint name="shooter_joint" type="fixed">
        <origin xyz="0 0.003 -0.074" rpy="0 0 0" />
        <parent link="base_link" />
        <child link="shooter_link" />
    </joint>

    <link name="camera_base_link">
        <inertial>
            <origin xyz="-5.2307E-05 -1.5998E-05 0.00049253" rpy="0 0 0" />
            <mass value="0.15794" />
            <inertia ixx="7.7178E-05" ixy="-7.743E-08" ixz="-1.6158E-07" iyy="0.00010028" iyz="-2.0158E-08" izz="0.00010682" />
        </inertial>
        <visual>
            <origin xyz="0 0 0" rpy="0 0 0" />
            <geometry>
                <mesh filename="package://rm_pioneer_description/meshes/guard/camera_base_link.stl" />
            </geometry>
            <material name="">
                <color rgba="1 1 1 1" />
            </material>
        </visual>
        <collision>
            <origin xyz="0 0 0" rpy="0 0 0" />
            <geometry>
                <mesh filename="package://rm_pioneer_description/meshes/guard/camera_base_link.stl" />
            </geometry>
        </collision>
    </link>

    <joint name="camera_joint" type="fixed">
        <origin xyz="0.132 0 -0.048" rpy="0 0 0" />
        <parent link="pitch_link" />
        <child link="camera_base_link" />
        <axis xyz="0 0 0" />
    </joint>

    <link name="camera_optical_frame" />

    <joint name="camera_optical_joint" type="fixed">
        <origin xyz="0 0 0" rpy="${pi/2} 0 ${pi/2}" />
        <parent link="camera_base_link" />
        <child link="camera_optical_frame" />
    </joint>

    <xacro:rm_serial_port/>
</robot>